
Saved Logging on: 2023-11-30 14:39:49
Error executing the script. Error: Traceback (most recent call last):
  File "D:\PYT\FLASK 2 auto\TAKE 57 IANA get\analyzer.py", line 896, in <module>
    classified_df = pd.read_csv('complete_connection.csv')
                    ^^^^^^^^^^^^^^^^^^^^^^^^^^^^^^^^^^^^^^
  File "D:\ABProgram Files\Python\Lib\site-packages\pandas\io\parsers\readers.py", line 948, in read_csv
    return _read(filepath_or_buffer, kwds)
           ^^^^^^^^^^^^^^^^^^^^^^^^^^^^^^^
  File "D:\ABProgram Files\Python\Lib\site-packages\pandas\io\parsers\readers.py", line 611, in _read
    parser = TextFileReader(filepath_or_buffer, **kwds)
             ^^^^^^^^^^^^^^^^^^^^^^^^^^^^^^^^^^^^^^^^^^
  File "D:\ABProgram Files\Python\Lib\site-packages\pandas\io\parsers\readers.py", line 1448, in __init__
    self._engine = self._make_engine(f, self.engine)
                   ^^^^^^^^^^^^^^^^^^^^^^^^^^^^^^^^^
  File "D:\ABProgram Files\Python\Lib\site-packages\pandas\io\parsers\readers.py", line 1705, in _make_engine
    self.handles = get_handle(
                   ^^^^^^^^^^^
  File "D:\ABProgram Files\Python\Lib\site-packages\pandas\io\common.py", line 863, in get_handle
    handle = open(
             ^^^^^
FileNotFoundError: [Errno 2] No such file or directory: 'complete_connection.csv'



Saved Logging on: 2023-11-30 14:39:40
Error executing the script. Error: Traceback (most recent call last):
  File "D:\PYT\FLASK 2 auto\TAKE 57 IANA get\analyzer.py", line 1042, in <module>
    filtered_df = df[df["modified"] >= seven_days_ago]
                     ^^^^^^^^^^^^^^^^^^^^^^^^^^^^^^^^
  File "D:\ABProgram Files\Python\Lib\site-packages\pandas\core\ops\common.py", line 76, in new_method
    return method(self, other)
           ^^^^^^^^^^^^^^^^^^^
  File "D:\ABProgram Files\Python\Lib\site-packages\pandas\core\arraylike.py", line 60, in __ge__
    return self._cmp_method(other, operator.ge)
           ^^^^^^^^^^^^^^^^^^^^^^^^^^^^^^^^^^^^
  File "D:\ABProgram Files\Python\Lib\site-packages\pandas\core\series.py", line 5799, in _cmp_method
    res_values = ops.comparison_op(lvalues, rvalues, op)
                 ^^^^^^^^^^^^^^^^^^^^^^^^^^^^^^^^^^^^^^^
  File "D:\ABProgram Files\Python\Lib\site-packages\pandas\core\ops\array_ops.py", line 346, in comparison_op
    res_values = comp_method_OBJECT_ARRAY(op, lvalues, rvalues)
                 ^^^^^^^^^^^^^^^^^^^^^^^^^^^^^^^^^^^^^^^^^^^^^^
  File "D:\ABProgram Files\Python\Lib\site-packages\pandas\core\ops\array_ops.py", line 131, in comp_method_OBJECT_ARRAY
    result = libops.scalar_compare(x.ravel(), y, op)
             ^^^^^^^^^^^^^^^^^^^^^^^^^^^^^^^^^^^^^^^
  File "ops.pyx", line 107, in pandas._libs.ops.scalar_compare
TypeError: '>=' not supported between instances of 'str' and 'datetime.datetime'
POWERED BY NG-Connection [AUTO] Threat Verdict
PROCESSING........