Error executing the script. Error: Traceback (most recent call last):
  File "F:\PYT\FLASK 2 auto\TAKE 33 cloning sync\analyzer.py", line 583, in <module>
    classified_df = pd.read_csv('classified_addressing.csv')
                    ^^^^^^^^^^^^^^^^^^^^^^^^^^^^^^^^^^^^^^^^
  File "C:\Users\Administrator\AppData\Local\Programs\Python\Python312\Lib\site-packages\pandas\io\parsers\readers.py", line 948, in read_csv
    return _read(filepath_or_buffer, kwds)
           ^^^^^^^^^^^^^^^^^^^^^^^^^^^^^^^
  File "C:\Users\Administrator\AppData\Local\Programs\Python\Python312\Lib\site-packages\pandas\io\parsers\readers.py", line 611, in _read
    parser = TextFileReader(filepath_or_buffer, **kwds)
             ^^^^^^^^^^^^^^^^^^^^^^^^^^^^^^^^^^^^^^^^^^
  File "C:\Users\Administrator\AppData\Local\Programs\Python\Python312\Lib\site-packages\pandas\io\parsers\readers.py", line 1448, in __init__
    self._engine = self._make_engine(f, self.engine)
                   ^^^^^^^^^^^^^^^^^^^^^^^^^^^^^^^^^
  File "C:\Users\Administrator\AppData\Local\Programs\Python\Python312\Lib\site-packages\pandas\io\parsers\readers.py", line 1705, in _make_engine
    self.handles = get_handle(
                   ^^^^^^^^^^^
  File "C:\Users\Administrator\AppData\Local\Programs\Python\Python312\Lib\site-packages\pandas\io\common.py", line 863, in get_handle
    handle = open(
             ^^^^^
FileNotFoundError: [Errno 2] No such file or directory: 'classified_addressing.csv'
